{"name": "test_get_events_sample_file", "status": "broken", "statusDetails": {"message": "AttributeError: 'str' object has no attribute 'items'", "trace": "def test_get_events_sample_file():\n>       response = test.api_tests.conftest.events_api.get_events_sample_file()\n\ntest_events_positive.py:28: \n_ _ _ _ _ _ _ _ _ _ _ _ _ _ _ _ _ _ _ _ _ _ _ _ _ _ _ _ _ _ _ _ _ _ _ _ _ _ _ _ \n../../api_service/events_api.py:74: in get_events_sample_file\n    return (self.api_executor.get(\n../../api_service/base_api.py:17: in get\n    return self.__execute_request('get', url=url, params=params, headers=headers)\n../../api_service/base_api.py:8: in __execute_request\n    return requests.request(\n/Library/Frameworks/Python.framework/Versions/3.12/lib/python3.12/site-packages/requests/api.py:59: in request\n    return session.request(method=method, url=url, **kwargs)\n/Library/Frameworks/Python.framework/Versions/3.12/lib/python3.12/site-packages/requests/sessions.py:575: in request\n    prep = self.prepare_request(req)\n/Library/Frameworks/Python.framework/Versions/3.12/lib/python3.12/site-packages/requests/sessions.py:486: in prepare_request\n    p.prepare(\n/Library/Frameworks/Python.framework/Versions/3.12/lib/python3.12/site-packages/requests/models.py:369: in prepare\n    self.prepare_headers(headers)\n_ _ _ _ _ _ _ _ _ _ _ _ _ _ _ _ _ _ _ _ _ _ _ _ _ _ _ _ _ _ _ _ _ _ _ _ _ _ _ _ \n\nself = <PreparedRequest [GET]>\nheaders = \"{'Authorization': 'Bearer eyJraWQiOiJzXC83Q3lJTWhIRGFHZVFWaFM4QjhKZVhGdmJTSElVUWVieWdQOGVUaGltWT0iLCJhbGciOiJSUzI1NiJ...y6tRoT7S3bLPUEezBCnRXkK5-SMbkDtk5ne-xZTSrMshJSc3dfjVxJoomWksvIo8nH830bN5JQCXdvdtVNgpppzClaADka9PzZ_Lo7QPkyZJUDkf90-g'}\"\n\n    def prepare_headers(self, headers):\n        \"\"\"Prepares the given HTTP headers.\"\"\"\n    \n        self.headers = CaseInsensitiveDict()\n        if headers:\n>           for header in headers.items():\nE           AttributeError: 'str' object has no attribute 'items'\n\n/Library/Frameworks/Python.framework/Versions/3.12/lib/python3.12/site-packages/requests/models.py:489: AttributeError"}, "start": 1715116940968, "stop": 1715116940969, "uuid": "f33cfaea-1509-4a6f-bea7-aec76657e1c7", "historyId": "0792b1db1d20f6b2e5cc6da479330e02", "testCaseId": "0792b1db1d20f6b2e5cc6da479330e02", "fullName": "test.api_tests.test_events_positive#test_get_events_sample_file", "labels": [{"name": "parentSuite", "value": "test.api_tests"}, {"name": "suite", "value": "test_events_positive"}, {"name": "host", "value": "dariias-mbp.home"}, {"name": "thread", "value": "81436-MainThread"}, {"name": "framework", "value": "pytest"}, {"name": "language", "value": "cpython3"}, {"name": "package", "value": "test.api_tests.test_events_positive"}]}